Workbook

Sheet Chapter 3
A1: Cultivar/Experiment/condition | B1: Sample | C1: Mass (g) | D1: Acrylamide in vial (ppb) | E1: Acrylamide in sample (µg/kg) | F1: Acrylamide band | G1: Expected chip colour | H1: Not like this | I1: Image file name
A2: Lady Claire Sulphur treated | B2: 1 | C2: 1.0146 | D2: 27.046 | E2: =D2*10/C2 -> 266.56811 | F2: =IF(NOT(ISNUMBER(E2)),"",IF(E2<Bands!$B$4,"Low",IF(E2<Bands!$B$5,"Medium",IF(E2<Bands!$B$6,"High","Very high")))) -> Low | G2: =IF(F2="","",IFERROR(INDEX(Bands!$D$3:$D$6,MATCH(F2,Bands!$A$3:$A$6,0)),"")) -> Pale yellow to light golden, even colour, no brown spots | H2: =IF(F2="","",IFERROR(INDEX(Bands!$J$3:$J$6,MATCH(F2,Bands!$A$3:$A$6,0)),"")) -> Not deep golden-brown or reddish-brown (those match higher values). Avoid black or burnt chips. | I2: =IF(F2="","","Ch3_"&TEXT(COUNT($E$2:E2),"000")&"_"&SUBSTITUTE(F2," ","-")&"_"&TEXT(E2,"0")&".jpg") -> Ch3_001_Low_267.jpg
B3: 2 | C3: 1.0498 | D3: 45.254 | E3: =D3*10/C3 -> 431.07259 | F3: =IF(NOT(ISNUMBER(E3)),"",IF(E3<Bands!$B$4,"Low",IF(E3<Bands!$B$5,"Medium",IF(E3<Bands!$B$6,"High","Very high")))) -> Low | G3: =IF(F3="","",IFERROR(INDEX(Bands!$D$3:$D$6,MATCH(F3,Bands!$A$3:$A$6,0)),"")) -> Pale yellow to light golden, even colour, no brown spots | H3: =IF(F3="","",IFERROR(INDEX(Bands!$J$3:$J$6,MATCH(F3,Bands!$A$3:$A$6,0)),"")) -> Not deep golden-brown or reddish-brown (those match higher values). Avoid black or burnt chips. | I3: =IF(F3="","","Ch3_"&TEXT(COUNT($E$2:E3),"000")&"_"&SUBSTITUTE(F3," ","-")&"_"&TEXT(E3,"0")&".jpg") -> Ch3_002_Low_431.jpg
B4: 3 | C4: 1.0058 | D4: 40.302 | E4: =D4*10/C4 -> 400.69596 | F4: =IF(NOT(ISNUMBER(E4)),"",IF(E4<Bands!$B$4,"Low",IF(E4<Bands!$B$5,"Medium",IF(E4<Bands!$B$6,"High","Very high")))) -> Low | G4: =IF(F4="","",IFERROR(INDEX(Bands!$D$3:$D$6,MATCH(F4,Bands!$A$3:$A$6,0)),"")) -> Pale yellow to light golden, even colour, no brown spots | H4: =IF(F4="","",IFERROR(INDEX(Bands!$J$3:$J$6,MATCH(F4,Bands!$A$3:$A$6,0)),"")) -> Not deep golden-brown or reddish-brown (those match higher values). Avoid black or burnt chips. | I4: =IF(F4="","","Ch3_"&TEXT(COUNT($E$2:E4),"000")&"_"&SUBSTITUTE(F4," ","-")&"_"&TEXT(E4,"0")&".jpg") -> Ch3_003_Low_401.jpg
B5: 4 | C5: 1.0215 | D5: 24.669 | E5: =D5*10/C5 -> 241.4978 | F5: =IF(NOT(ISNUMBER(E5)),"",IF(E5<Bands!$B$4,"Low",IF(E5<Bands!$B$5,"Medium",IF(E5<Bands!$B$6,"High","Very high")))) -> Low | G5: =IF(F5="","",IFERROR(INDEX(Bands!$D$3:$D$6,MATCH(F5,Bands!$A$3:$A$6,0)),"")) -> Pale yellow to light golden, even colour, no brown spots | H5: =IF(F5="","",IFERROR(INDEX(Bands!$J$3:$J$6,MATCH(F5,Bands!$A$3:$A$6,0)),"")) -> Not deep golden-brown or reddish-brown (those match higher values). Avoid black or burnt chips. | I5: =IF(F5="","","Ch3_"&TEXT(COUNT($E$2:E5),"000")&"_"&SUBSTITUTE(F5," ","-")&"_"&TEXT(E5,"0")&".jpg") -> Ch3_004_Low_241.jpg
B6: 5 | C6: 1.0016 | D6: 21.529 | E6: =D6*10/C6 -> 214.94609 | F6: =IF(NOT(ISNUMBER(E6)),"",IF(E6<Bands!$B$4,"Low",IF(E6<Bands!$B$5,"Medium",IF(E6<Bands!$B$6,"High","Very high")))) -> Low | G6: =IF(F6="","",IFERROR(INDEX(Bands!$D$3:$D$6,MATCH(F6,Bands!$A$3:$A$6,0)),"")) -> Pale yellow to light golden, even colour, no brown spots | H6: =IF(F6="","",IFERROR(INDEX(Bands!$J$3:$J$6,MATCH(F6,Bands!$A$3:$A$6,0)),"")) -> Not deep golden-brown or reddish-brown (those match higher values). Avoid black or burnt chips. | I6: =IF(F6="","","Ch3_"&TEXT(COUNT($E$2:E6),"000")&"_"&SUBSTITUTE(F6," ","-")&"_"&TEXT(E6,"0")&".jpg") -> Ch3_005_Low_215.jpg
B7: 6 | C7: 1.0076 | D7: 14.46 | E7: =D7*10/C7 -> 143.50933 | F7: =IF(NOT(ISNUMBER(E7)),"",IF(E7<Bands!$B$4,"Low",IF(E7<Bands!$B$5,"Medium",IF(E7<Bands!$B$6,"High","Very high")))) -> Low | G7: =IF(F7="","",IFERROR(INDEX(Bands!$D$3:$D$6,MATCH(F7,Bands!$A$3:$A$6,0)),"")) -> Pale yellow to light golden, even colour, no brown spots | H7: =IF(F7="","",IFERROR(INDEX(Bands!$J$3:$J$6,MATCH(F7,Bands!$A$3:$A$6,0)),"")) -> Not deep golden-brown or reddish-brown (those match higher values). Avoid black or burnt chips. | I7: =IF(F7="","","Ch3_"&TEXT(COUNT($E$2:E7),"000")&"_"&SUBSTITUTE(F7," ","-")&"_"&TEXT(E7,"0")&".jpg") -> Ch3_006_Low_144.jpg
B8: 7 | C8: 0.9967 | D8: 41.986 | E8: =D8*10/C8 -> 421.25013 | F8: =IF(NOT(ISNUMBER(E8)),"",IF(E8<Bands!$B$4,"Low",IF(E8<Bands!$B$5,"Medium",IF(E8<Bands!$B$6,"High","Very high")))) -> Low | G8: =IF(F8="","",IFERROR(INDEX(Bands!$D$3:$D$6,MATCH(F8,Bands!$A$3:$A$6,0)),"")) -> Pale yellow to light golden, even colour, no brown spots | H8: =IF(F8="","",IFERROR(INDEX(Bands!$J$3:$J$6,MATCH(F8,Bands!$A$3:$A$6,0)),"")) -> Not deep golden-brown or reddish-brown (those match higher values). Avoid black or burnt chips. | I8: =IF(F8="","","Ch3_"&TEXT(COUNT($E$2:E8),"000")&"_"&SUBSTITUTE(F8," ","-")&"_"&TEXT(E8,"0")&".jpg") -> Ch3_007_Low_421.jpg
B9: 8 | C9: 1.0428 | D9: 53.732 | E9: =D9*10/C9 -> 515.26659 | F9: =IF(NOT(ISNUMBER(E9)),"",IF(E9<Bands!$B$4,"Low",IF(E9<Bands!$B$5,"Medium",IF(E9<Bands!$B$6,"High","Very high")))) -> Medium | G9: =IF(F9="","",IFERROR(INDEX(Bands!$D$3:$D$6,MATCH(F9,Bands!$A$3:$A$6,0)),"")) -> Golden yellow with light brown at some edges or small spots | H9: =IF(F9="","",IFERROR(INDEX(Bands!$J$3:$J$6,MATCH(F9,Bands!$A$3:$A$6,0)),"")) -> Not pale yellow (matches a low value) and not deep reddish-brown (matches a high value). Avoid black or burnt chips. | I9: =IF(F9="","","Ch3_"&TEXT(COUNT($E$2:E9),"000")&"_"&SUBSTITUTE(F9," ","-")&"_"&TEXT(E9,"0")&".jpg") -> Ch3_008_Medium_515.jpg
B10: 9 | C10: 1.0069 | D10: 32.267 | E10: =D10*10/C10 -> 320.45883 | F10: =IF(NOT(ISNUMBER(E10)),"",IF(E10<Bands!$B$4,"Low",IF(E10<Bands!$B$5,"Medium",IF(E10<Bands!$B$6,"High","Very high")))) -> Low | G10: =IF(F10="","",IFERROR(INDEX(Bands!$D$3:$D$6,MATCH(F10,Bands!$A$3:$A$6,0)),"")) -> Pale yellow to light golden, even colour, no brown spots | H10: =IF(F10="","",IFERROR(INDEX(Bands!$J$3:$J$6,MATCH(F10,Bands!$A$3:$A$6,0)),"")) -> Not deep golden-brown or reddish-brown (those match higher values). Avoid black or burnt chips. | I10: =IF(F10="","","Ch3_"&TEXT(COUNT($E$2:E10),"000")&"_"&SUBSTITUTE(F10," ","-")&"_"&TEXT(E10,"0")&".jpg") -> Ch3_009_Low_320.jpg
B11: 10 | C11: 1.0256 | D11: 29.128 | E11: =D11*10/C11 -> 284.00936 | F11: =IF(NOT(ISNUMBER(E11)),"",IF(E11<Bands!$B$4,"Low",IF(E11<Bands!$B$5,"Medium",IF(E11<Bands!$B$6,"High","Very high")))) -> Low | G11: =IF(F11="","",IFERROR(INDEX(Bands!$D$3:$D$6,MATCH(F11,Bands!$A$3:$A$6,0)),"")) -> Pale yellow to light golden, even colour, no brown spots | H11: =IF(F11="","",IFERROR(INDEX(Bands!$J$3:$J$6,MATCH(F11,Bands!$A$3:$A$6,0)),"")) -> Not deep golden-brown or reddish-brown (those match higher values). Avoid black or burnt chips. | I11: =IF(F11="","","Ch3_"&TEXT(COUNT($E$2:E11),"000")&"_"&SUBSTITUTE(F11," ","-")&"_"&TEXT(E11,"0")&".jpg") -> Ch3_010_Low_284.jpg
B12: 11 | C12: 1.0241 | D12: 15.857 | E12: =D12*10/C12 -> 154.83839 | F12: =IF(NOT(ISNUMBER(E12)),"",IF(E12<Bands!$B$4,"Low",IF(E12<Bands!$B$5,"Medium",IF(E12<Bands!$B$6,"High","Very high")))) -> Low | G12: =IF(F12="","",IFERROR(INDEX(Bands!$D$3:$D$6,MATCH(F12,Bands!$A$3:$A$6,0)),"")) -> Pale yellow to light golden, even colour, no brown spots | H12: =IF(F12="","",IFERROR(INDEX(Bands!$J$3:$J$6,MATCH(F12,Bands!$A$3:$A$6,0)),"")) -> Not deep golden-brown or reddish-brown (those match higher values). Avoid black or burnt chips. | I12: =IF(F12="","","Ch3_"&TEXT(COUNT($E$2:E12),"000")&"_"&SUBSTITUTE(F12," ","-")&"_"&TEXT(E12,"0")&".jpg") -> Ch3_011_Low_155.jpg
B13: 12 | C13: 1.0144 | D13: 27.018 | E13: =D13*10/C13 -> 266.34464 | F13: =IF(NOT(ISNUMBER(E13)),"",IF(E13<Bands!$B$4,"Low",IF(E13<Bands!$B$5,"Medium",IF(E13<Bands!$B$6,"High","Very high")))) -> Low | G13: =IF(F13="","",IFERROR(INDEX(Bands!$D$3:$D$6,MATCH(F13,Bands!$A$3:$A$6,0)),"")) -> Pale yellow to light golden, even colour, no brown spots | H13: =IF(F13="","",IFERROR(INDEX(Bands!$J$3:$J$6,MATCH(F13,Bands!$A$3:$A$6,0)),"")) -> Not deep golden-brown or reddish-brown (those match higher values). Avoid black or burnt chips. | I13: =IF(F13="","","Ch3_"&TEXT(COUNT($E$2:E13),"000")&"_"&SUBSTITUTE(F13," ","-")&"_"&TEXT(E13,"0")&".jpg") -> Ch3_012_Low_266.jpg
B14: 13 | C14: 1.0529 | D14: 41.954 | E14: =D14*10/C14 -> 398.46139 | F14: =IF(NOT(ISNUMBER(E14)),"",IF(E14<Bands!$B$4,"Low",IF(E14<Bands!$B$5,"Medium",IF(E14<Bands!$B$6,"High","Very high")))) -> Low | G14: =IF(F14="","",IFERROR(INDEX(Bands!$D$3:$D$6,MATCH(F14,Bands!$A$3:$A$6,0)),"")) -> Pale yellow to light golden, even colour, no brown spots | H14: =IF(F14="","",IFERROR(INDEX(Bands!$J$3:$J$6,MATCH(F14,Bands!$A$3:$A$6,0)),"")) -> Not deep golden-brown or reddish-brown (those match higher values). Avoid black or burnt chips. | I14: =IF(F14="","","Ch3_"&TEXT(COUNT($E$2:E14),"000")&"_"&SUBSTITUTE(F14," ","-")&"_"&TEXT(E14,"0")&".jpg") -> Ch3_013_Low_398.jpg
... B25: 24 | C25: 1.0172 | D25: 32.259 | E25: =D25*10/C25 -> 317.13527 | F25: =IF(NOT(ISNUMBER(E25)),"",IF(E25<Bands!$B$4,"Low",IF(E25<Bands!$B$5,"Medium",IF(E25<Bands!$B$6,"High","Very high")))) -> Low | G25: =IF(F25="","",IFERROR(INDEX(Bands!$D$3:$D$6,MATCH(F25,Bands!$A$3:$A$6,0)),"")) -> Pale yellow to light golden, even colour, no brown spots | H25: =IF(F25="","",IFERROR(INDEX(Bands!$J$3:$J$6,MATCH(F25,Bands!$A$3:$A$6,0)),"")) -> Not deep golden-brown or reddish-brown (those match higher values). Avoid black or burnt chips. | I25: =IF(F25="","","Ch3_"&TEXT(COUNT($E$2:E25),"000")&"_"&SUBSTITUTE(F25," ","-")&"_"&TEXT(E25,"0")&".jpg") -> Ch3_024_Low_317.jpg
A27: Lady Claire Sulphur controls | B27: 1 | C27: 0.9966 | D27: 47.158 | E27: =D27*10/C27 -> 473.18884 | F27: =IF(NOT(ISNUMBER(E27)),"",IF(E27<Bands!$B$4,"Low",IF(E27<Bands!$B$5,"Medium",IF(E27<Bands!$B$6,"High","Very high")))) -> Low | G27: =IF(F27="","",IFERROR(INDEX(Bands!$D$3:$D$6,MATCH(F27,Bands!$A$3:$A$6,0)),"")) -> Pale yellow to light golden, even colour, no brown spots | H27: =IF(F27="","",IFERROR(INDEX(Bands!$J$3:$J$6,MATCH(F27,Bands!$A$3:$A$6,0)),"")) -> Not deep golden-brown or reddish-brown (those match higher values). Avoid black or burnt chips. | I27: =IF(F27="","","Ch3_"&TEXT(COUNT($E$2:E27),"000")&"_"&SUBSTITUTE(F27," ","-")&"_"&TEXT(E27,"0")&".jpg") -> Ch3_025_Low_473.jpg
B28: 2 | C28: 0.9707 | D28: 33.109 | E28: =D28*10/C28 -> 341.08375 | F28: =IF(NOT(ISNUMBER(E28)),"",IF(E28<Bands!$B$4,"Low",IF(E28<Bands!$B$5,"Medium",IF(E28<Bands!$B$6,"High","Very high")))) -> Low | G28: =IF(F28="","",IFERROR(INDEX(Bands!$D$3:$D$6,MATCH(F28,Bands!$A$3:$A$6,0)),"")) -> Pale yellow to light golden, even colour, no brown spots | H28: =IF(F28="","",IFERROR(INDEX(Bands!$J$3:$J$6,MATCH(F28,Bands!$A$3:$A$6,0)),"")) -> Not deep golden-brown or reddish-brown (those match higher values). Avoid black or burnt chips. | I28: =IF(F28="","","Ch3_"&TEXT(COUNT($E$2:E28),"000")&"_"&SUBSTITUTE(F28," ","-")&"_"&TEXT(E28,"0")&".jpg") -> Ch3_026_Low_341.jpg
B29: 3 | C29: 0.9929 | D29: 8.81 | E29: =D29*10/C29 -> 88.729983 | F29: =IF(NOT(ISNUMBER(E29)),"",IF(E29<Bands!$B$4,"Low",IF(E29<Bands!$B$5,"Medium",IF(E29<Bands!$B$6,"High","Very high")))) -> Low | G29: =IF(F29="","",IFERROR(INDEX(Bands!$D$3:$D$6,MATCH(F29,Bands!$A$3:$A$6,0)),"")) -> Pale yellow to light golden, even colour, no brown spots | H29: =IF(F29="","",IFERROR(INDEX(Bands!$J$3:$J$6,MATCH(F29,Bands!$A$3:$A$6,0)),"")) -> Not deep golden-brown or reddish-brown (those match higher values). Avoid black or burnt chips. | I29: =IF(F29="","","Ch3_"&TEXT(COUNT($E$2:E29),"000")&"_"&SUBSTITUTE(F29," ","-")&"_"&TEXT(E29,"0")&".jpg") -> Ch3_027_Low_89.jpg
B30: 4 | C30: 0.9878 | D30: 16.625 | E30: =D30*10/C30 -> 168.3033 | F30: =IF(NOT(ISNUMBER(E30)),"",IF(E30<Bands!$B$4,"Low",IF(E30<Bands!$B$5,"Medium",IF(E30<Bands!$B$6,"High","Very high")))) -> Low | G30: =IF(F30="","",IFERROR(INDEX(Bands!$D$3:$D$6,MATCH(F30,Bands!$A$3:$A$6,0)),"")) -> Pale yellow to light golden, even colour, no brown spots | H30: =IF(F30="","",IFERROR(INDEX(Bands!$J$3:$J$6,MATCH(F30,Bands!$A$3:$A$6,0)),"")) -> Not deep golden-brown or reddish-brown (those match higher values). Avoid black or burnt chips. | I30: =IF(F30="","","Ch3_"&TEXT(COUNT($E$2:E30),"000")&"_"&SUBSTITUTE(F30," ","-")&"_"&TEXT(E30,"0")&".jpg") -> Ch3_028_Low_168.jpg
B31: 5 | C31: 1.0429 | D31: 17.283 | E31: =D31*10/C31 -> 165.72059 | F31: =IF(NOT(ISNUMBER(E31)),"",IF(E31<Bands!$B$4,"Low",IF(E31<Bands!$B$5,"Medium",IF(E31<Bands!$B$6,"High","Very high")))) -> Low | G31: =IF(F31="","",IFERROR(INDEX(Bands!$D$3:$D$6,MATCH(F31,Bands!$A$3:$A$6,0)),"")) -> Pale yellow to light golden, even colour, no brown spots | H31: =IF(F31="","",IFERROR(INDEX(Bands!$J$3:$J$6,MATCH(F31,Bands!$A$3:$A$6,0)),"")) -> Not deep golden-brown or reddish-brown (those match higher values). Avoid black or burnt chips. | I31: =IF(F31="","","Ch3_"&TEXT(COUNT($E$2:E31),"000")&"_"&SUBSTITUTE(F31," ","-")&"_"&TEXT(E31,"0")&".jpg") -> Ch3_029_Low_166.jpg
B32: 6 | C32: 1.03 | D32: 26.897 | E32: =D32*10/C32 -> 261.13592 | F32: =IF(NOT(ISNUMBER(E32)),"",IF(E32<Bands!$B$4,"Low",IF(E32<Bands!$B$5,"Medium",IF(E32<Bands!$B$6,"High","Very high")))) -> Low | G32: =IF(F32="","",IFERROR(INDEX(Bands!$D$3:$D$6,MATCH(F32,Bands!$A$3:$A$6,0)),"")) -> Pale yellow to light golden, even colour, no brown spots | H32: =IF(F32="","",IFERROR(INDEX(Bands!$J$3:$J$6,MATCH(F32,Bands!$A$3:$A$6,0)),"")) -> Not deep golden-brown or reddish-brown (those match higher values). Avoid black or burnt chips. | I32: =IF(F32="","","Ch3_"&TEXT(COUNT($E$2:E32),"000")&"_"&SUBSTITUTE(F32," ","-")&"_"&TEXT(E32,"0")&".jpg") -> Ch3_030_Low_261.jpg
B33: 7 | C33: 0.9664 | D33: 17.66 | E33: =D33*10/C33 -> 182.74007 | F33: =IF(NOT(ISNUMBER(E33)),"",IF(E33<Bands!$B$4,"Low",IF(E33<Bands!$B$5,"Medium",IF(E33<Bands!$B$6,"High","Very high")))) -> Low | G33: =IF(F33="","",IFERROR(INDEX(Bands!$D$3:$D$6,MATCH(F33,Bands!$A$3:$A$6,0)),"")) -> Pale yellow to light golden, even colour, no brown spots | H33: =IF(F33="","",IFERROR(INDEX(Bands!$J$3:$J$6,MATCH(F33,Bands!$A$3:$A$6,0)),"")) -> Not deep golden-brown or reddish-brown (those match higher values). Avoid black or burnt chips. | I33: =IF(F33="","","Ch3_"&TEXT(COUNT($E$2:E33),"000")&"_"&SUBSTITUTE(F33," ","-")&"_"&TEXT(E33,"0")&".jpg") -> Ch3_031_Low_183.jpg
B34: 8 | C34: 1.0124 | D34: 21.729 | E34: =D34*10/C34 -> 214.62861 | F34: =IF(NOT(ISNUMBER(E34)),"",IF(E34<Bands!$B$4,"Low",IF(E34<Bands!$B$5,"Medium",IF(E34<Bands!$B$6,"High","Very high")))) -> Low | G34: =IF(F34="","",IFERROR(INDEX(Bands!$D$3:$D$6,MATCH(F34,Bands!$A$3:$A$6,0)),"")) -> Pale yellow to light golden, even colour, no brown spots | H34: =IF(F34="","",IFERROR(INDEX(Bands!$J$3:$J$6,MATCH(F34,Bands!$A$3:$A$6,0)),"")) -> Not deep golden-brown or reddish-brown (those match higher values). Avoid black or burnt chips. | I34: =IF(F34="","","Ch3_"&TEXT(COUNT($E$2:E34),"000")&"_"&SUBSTITUTE(F34," ","-")&"_"&TEXT(E34,"0")&".jpg") -> Ch3_032_Low_215.jpg
B35: 9 | C35: 1.0051 | D35: 20.524 | E35: =D35*10/C35 -> 204.19859 | F35: =IF(NOT(ISNUMBER(E35)),"",IF(E35<Bands!$B$4,"Low",IF(E35<Bands!$B$5,"Medium",IF(E35<Bands!$B$6,"High","Very high")))) -> Low | G35: =IF(F35="","",IFERROR(INDEX(Bands!$D$3:$D$6,MATCH(F35,Bands!$A$3:$A$6,0)),"")) -> Pale yellow to light golden, even colour, no brown spots | H35: =IF(F35="","",IFERROR(INDEX(Bands!$J$3:$J$6,MATCH(F35,Bands!$A$3:$A$6,0)),"")) -> Not deep golden-brown or reddish-brown (those match higher values). Avoid black or burnt chips. | I35: =IF(F35="","","Ch3_"&TEXT(COUNT($E$2:E35),"000")&"_"&SUBSTITUTE(F35," ","-")&"_"&TEXT(E35,"0")&".jpg") -> Ch3_033_Low_204.jpg
B36: 10 | C36: 0.9927 | D36: 45.906 | E36: =D36*10/C36 -> 462.43578 | F36: =IF(NOT(ISNUMBER(E36)),"",IF(E36<Bands!$B$4,"Low",IF(E36<Bands!$B$5,"Medium",IF(E36<Bands!$B$6,"High","Very high")))) -> Low | G36: =IF(F36="","",IFERROR(INDEX(Bands!$D$3:$D$6,MATCH(F36,Bands!$A$3:$A$6,0)),"")) -> Pale yellow to light golden, even colour, no brown spots | H36: =IF(F36="","",IFERROR(INDEX(Bands!$J$3:$J$6,MATCH(F36,Bands!$A$3:$A$6,0)),"")) -> Not deep golden-brown or reddish-brown (those match higher values). Avoid black or burnt chips. | I36: =IF(F36="","","Ch3_"&TEXT(COUNT($E$2:E36),"000")&"_"&SUBSTITUTE(F36," ","-")&"_"&TEXT(E36,"0")&".jpg") -> Ch3_034_Low_462.jpg
B37: 11 | C37: 1.015 | D37: 64.177 | E37: =D37*10/C37 -> 632.28571 | F37: =IF(NOT(ISNUMBER(E37)),"",IF(E37<Bands!$B$4,"Low",IF(E37<Bands!$B$5,"Medium",IF(E37<Bands!$B$6,"High","Very high")))) -> Medium | G37: =IF(F37="","",IFERROR(INDEX(Bands!$D$3:$D$6,MATCH(F37,Bands!$A$3:$A$6,0)),"")) -> Golden yellow with light brown at some edges or small spots | H37: =IF(F37="","",IFERROR(INDEX(Bands!$J$3:$J$6,MATCH(F37,Bands!$A$3:$A$6,0)),"")) -> Not pale yellow (matches a low value) and not deep reddish-brown (matches a high value). Avoid black or burnt chips. | I37: =IF(F37="","","Ch3_"&TEXT(COUNT($E$2:E37),"000")&"_"&SUBSTITUTE(F37," ","-")&"_"&TEXT(E37,"0")&".jpg") -> Ch3_035_Medium_632.jpg
B38: 12 | C38: 0.9709 | D38: 52.087 | E38: =D38*10/C38 -> 536.48161 | F38: =IF(NOT(ISNUMBER(E38)),"",IF(E38<Bands!$B$4,"Low",IF(E38<Bands!$B$5,"Medium",IF(E38<Bands!$B$6,"High","Very high")))) -> Medium | G38: =IF(F38="","",IFERROR(INDEX(Bands!$D$3:$D$6,MATCH(F38,Bands!$A$3:$A$6,0)),"")) -> Golden yellow with light brown at some edges or small spots | H38: =IF(F38="","",IFERROR(INDEX(Bands!$J$3:$J$6,MATCH(F38,Bands!$A$3:$A$6,0)),"")) -> Not pale yellow (matches a low value) and not deep reddish-brown (matches a high value). Avoid black or burnt chips. | I38: =IF(F38="","","Ch3_"&TEXT(COUNT($E$2:E38),"000")&"_"&SUBSTITUTE(F38," ","-")&"_"&TEXT(E38,"0")&".jpg") -> Ch3_036_Medium_536.jpg
B39: 13 | C39: 1.0308 | D39: 17.525 | E39: =D39*10/C39 -> 170.01358 | F39: =IF(NOT(ISNUMBER(E39)),"",IF(E39<Bands!$B$4,"Low",IF(E39<Bands!$B$5,"Medium",IF(E39<Bands!$B$6,"High","Very high")))) -> Low | G39: =IF(F39="","",IFERROR(INDEX(Bands!$D$3:$D$6,MATCH(F39,Bands!$A$3:$A$6,0)),"")) -> Pale yellow to light golden, even colour, no brown spots | H39: =IF(F39="","",IFERROR(INDEX(Bands!$J$3:$J$6,MATCH(F39,Bands!$A$3:$A$6,0)),"")) -> Not deep golden-brown or reddish-brown (those match higher values). Avoid black or burnt chips. | I39: =IF(F39="","","Ch3_"&TEXT(COUNT($E$2:E39),"000")&"_"&SUBSTITUTE(F39," ","-")&"_"&TEXT(E39,"0")&".jpg") -> Ch3_037_Low_170.jpg
... B50: 24 | C50: 0.9881 | D50: 41.917 | E50: =D50*10/C50 -> 424.2182 | F50: =IF(NOT(ISNUMBER(E50)),"",IF(E50<Bands!$B$4,"Low",IF(E50<Bands!$B$5,"Medium",IF(E50<Bands!$B$6,"High","Very high")))) -> Low | G50: =IF(F50="","",IFERROR(INDEX(Bands!$D$3:$D$6,MATCH(F50,Bands!$A$3:$A$6,0)),"")) -> Pale yellow to light golden, even colour, no brown spots | H50: =IF(F50="","",IFERROR(INDEX(Bands!$J$3:$J$6,MATCH(F50,Bands!$A$3:$A$6,0)),"")) -> Not deep golden-brown or reddish-brown (those match higher values). Avoid black or burnt chips. | I50: =IF(F50="","","Ch3_"&TEXT(COUNT($E$2:E50),"000")&"_"&SUBSTITUTE(F50," ","-")&"_"&TEXT(E50,"0")&".jpg") -> Ch3_048_Low_424.jpg
A52: Taurus Sulphur treated | B52: 1 | C52: 1.03 | D52: 84.689 | E52: =D52*10/C52 -> 822.2233 | F52: =IF(NOT(ISNUMBER(E52)),"",IF(E52<Bands!$B$4,"Low",IF(E52<Bands!$B$5,"Medium",IF(E52<Bands!$B$6,"High","Very high")))) -> Medium | G52: =IF(F52="","",IFERROR(INDEX(Bands!$D$3:$D$6,MATCH(F52,Bands!$A$3:$A$6,0)),"")) -> Golden yellow with light brown at some edges or small spots | H52: =IF(F52="","",IFERROR(INDEX(Bands!$J$3:$J$6,MATCH(F52,Bands!$A$3:$A$6,0)),"")) -> Not pale yellow (matches a low value) and not deep reddish-brown (matches a high value). Avoid black or burnt chips. | I52: =IF(F52="","","Ch3_"&TEXT(COUNT($E$2:E52),"000")&"_"&SUBSTITUTE(F52," ","-")&"_"&TEXT(E52,"0")&".jpg") -> Ch3_049_Medium_822.jpg
B53: 2 | C53: 1.0039 | D53: 63.339 | E53: =D53*10/C53 -> 630.92938 | F53: =IF(NOT(ISNUMBER(E53)),"",IF(E53<Bands!$B$4,"Low",IF(E53<Bands!$B$5,"Medium",IF(E53<Bands!$B$6,"High","Very high")))) -> Medium | G53: =IF(F53="","",IFERROR(INDEX(Bands!$D$3:$D$6,MATCH(F53,Bands!$A$3:$A$6,0)),"")) -> Golden yellow with light brown at some edges or small spots | H53: =IF(F53="","",IFERROR(INDEX(Bands!$J$3:$J$6,MATCH(F53,Bands!$A$3:$A$6,0)),"")) -> Not pale yellow (matches a low value) and not deep reddish-brown (matches a high value). Avoid black or burnt chips. | I53: =IF(F53="","","Ch3_"&TEXT(COUNT($E$2:E53),"000")&"_"&SUBSTITUTE(F53," ","-")&"_"&TEXT(E53,"0")&".jpg") -> Ch3_050_Medium_631.jpg
B54: 3 | C54: 0.9615 | D54: 141.608 | E54: =D54*10/C54 -> 1472.7821 | F54: =IF(NOT(ISNUMBER(E54)),"",IF(E54<Bands!$B$4,"Low",IF(E54<Bands!$B$5,"Medium",IF(E54<Bands!$B$6,"High","Very high")))) -> High | G54: =IF(F54="","",IFERROR(INDEX(Bands!$D$3:$D$6,MATCH(F54,Bands!$A$3:$A$6,0)),"")) -> Golden-brown with a reddish tint, brown edges, somewhat uneven | H54: =IF(F54="","",IFERROR(INDEX(Bands!$J$3:$J$6,MATCH(F54,Bands!$A$3:$A$6,0)),"")) -> Not pale yellow, which would match a low value. Not black or burnt, since very dark chips can have lower acrylamide. | I54: =IF(F54="","","Ch3_"&TEXT(COUNT($E$2:E54),"000")&"_"&SUBSTITUTE(F54," ","-")&"_"&TEXT(E54,"0")&".jpg") -> Ch3_051_High_1473.jpg
B55: 4 | C55: 0.984 | D55: 88.892 | E55: =D55*10/C55 -> 903.37398 | F55: =IF(NOT(ISNUMBER(E55)),"",IF(E55<Bands!$B$4,"Low",IF(E55<Bands!$B$5,"Medium",IF(E55<Bands!$B$6,"High","Very high")))) -> Medium | G55: =IF(F55="","",IFERROR(INDEX(Bands!$D$3:$D$6,MATCH(F55,Bands!$A$3:$A$6,0)),"")) -> Golden yellow with light brown at some edges or small spots | H55: =IF(F55="","",IFERROR(INDEX(Bands!$J$3:$J$6,MATCH(F55,Bands!$A$3:$A$6,0)),"")) -> Not pale yellow (matches a low value) and not deep reddish-brown (matches a high value). Avoid black or burnt chips. | I55: =IF(F55="","","Ch3_"&TEXT(COUNT($E$2:E55),"000")&"_"&SUBSTITUTE(F55," ","-")&"_"&TEXT(E55,"0")&".jpg") -> Ch3_052_Medium_903.jpg
B56: 5 | C56: 0.9732 | D56: 32.794 | E56: =D56*10/C56 -> 336.97082 | F56: =IF(NOT(ISNUMBER(E56)),"",IF(E56<Bands!$B$4,"Low",IF(E56<Bands!$B$5,"Medium",IF(E56<Bands!$B$6,"High","Very high")))) -> Low | G56: =IF(F56="","",IFERROR(INDEX(Bands!$D$3:$D$6,MATCH(F56,Bands!$A$3:$A$6,0)),"")) -> Pale yellow to light golden, even colour, no brown spots | H56: =IF(F56="","",IFERROR(INDEX(Bands!$J$3:$J$6,MATCH(F56,Bands!$A$3:$A$6,0)),"")) -> Not deep golden-brown or reddish-brown (those match higher values). Avoid black or burnt chips. | I56: =IF(F56="","","Ch3_"&TEXT(COUNT($E$2:E56),"000")&"_"&SUBSTITUTE(F56," ","-")&"_"&TEXT(E56,"0")&".jpg") -> Ch3_053_Low_337.jpg
B57: 6 | C57: 0.9798 | D57: 42.668 | E57: =D57*10/C57 -> 435.47663 | F57: =IF(NOT(ISNUMBER(E57)),"",IF(E57<Bands!$B$4,"Low",IF(E57<Bands!$B$5,"Medium",IF(E57<Bands!$B$6,"High","Very high")))) -> Low | G57: =IF(F57="","",IFERROR(INDEX(Bands!$D$3:$D$6,MATCH(F57,Bands!$A$3:$A$6,0)),"")) -> Pale yellow to light golden, even colour, no brown spots | H57: =IF(F57="","",IFERROR(INDEX(Bands!$J$3:$J$6,MATCH(F57,Bands!$A$3:$A$6,0)),"")) -> Not deep golden-brown or reddish-brown (those match higher values). Avoid black or burnt chips. | I57: =IF(F57="","","Ch3_"&TEXT(COUNT($E$2:E57),"000")&"_"&SUBSTITUTE(F57," ","-")&"_"&TEXT(E57,"0")&".jpg") -> Ch3_054_Low_435.jpg
B58: 7 | C58: 0.9832 | D58: 55.679 | E58: =D58*10/C58 -> 566.30391 | F58: =IF(NOT(ISNUMBER(E58)),"",IF(E58<Bands!$B$4,"Low",IF(E58<Bands!$B$5,"Medium",IF(E58<Bands!$B$6,"High","Very high")))) -> Medium | G58: =IF(F58="","",IFERROR(INDEX(Bands!$D$3:$D$6,MATCH(F58,Bands!$A$3:$A$6,0)),"")) -> Golden yellow with light brown at some edges or small spots | H58: =IF(F58="","",IFERROR(INDEX(Bands!$J$3:$J$6,MATCH(F58,Bands!$A$3:$A$6,0)),"")) -> Not pale yellow (matches a low value) and not deep reddish-brown (matches a high value). Avoid black or burnt chips. | I58: =IF(F58="","","Ch3_"&TEXT(COUNT($E$2:E58),"000")&"_"&SUBSTITUTE(F58," ","-")&"_"&TEXT(E58,"0")&".jpg") -> Ch3_055_Medium_566.jpg
B59: 8 | C59: 0.9952 | D59: 56.965 | E59: =D59*10/C59 -> 572.39751 | F59: =IF(NOT(ISNUMBER(E59)),"",IF(E59<Bands!$B$4,"Low",IF(E59<Bands!$B$5,"Medium",IF(E59<Bands!$B$6,"High","Very high")))) -> Medium | G59: =IF(F59="","",IFERROR(INDEX(Bands!$D$3:$D$6,MATCH(F59,Bands!$A$3:$A$6,0)),"")) -> Golden yellow with light brown at some edges or small spots | H59: =IF(F59="","",IFERROR(INDEX(Bands!$J$3:$J$6,MATCH(F59,Bands!$A$3:$A$6,0)),"")) -> Not pale yellow (matches a low value) and not deep reddish-brown (matches a high value). Avoid black or burnt chips. | I59: =IF(F59="","","Ch3_"&TEXT(COUNT($E$2:E59),"000")&"_"&SUBSTITUTE(F59," ","-")&"_"&TEXT(E59,"0")&".jpg") -> Ch3_056_Medium_572.jpg
B60: 9 | C60: 1.0154 | D60: 150.898 | E60: =D60*10/C60 -> 1486.0942 | F60: =IF(NOT(ISNUMBER(E60)),"",IF(E60<Bands!$B$4,"Low",IF(E60<Bands!$B$5,"Medium",IF(E60<Bands!$B$6,"High","Very high")))) -> High | G60: =IF(F60="","",IFERROR(INDEX(Bands!$D$3:$D$6,MATCH(F60,Bands!$A$3:$A$6,0)),"")) -> Golden-brown with a reddish tint, brown edges, somewhat uneven | H60: =IF(F60="","",IFERROR(INDEX(Bands!$J$3:$J$6,MATCH(F60,Bands!$A$3:$A$6,0)),"")) -> Not pale yellow, which would match a low value. Not black or burnt, since very dark chips can have lower acrylamide. | I60: =IF(F60="","","Ch3_"&TEXT(COUNT($E$2:E60),"000")&"_"&SUBSTITUTE(F60," ","-")&"_"&TEXT(E60,"0")&".jpg") -> Ch3_057_High_1486.jpg
B61: 10 | C61: 0.9834 | D61: 51.029 | E61: =D61*10/C61 -> 518.9038 | F61: =IF(NOT(ISNUMBER(E61)),"",IF(E61<Bands!$B$4,"Low",IF(E61<Bands!$B$5,"Medium",IF(E61<Bands!$B$6,"High","Very high")))) -> Medium | G61: =IF(F61="","",IFERROR(INDEX(Bands!$D$3:$D$6,MATCH(F61,Bands!$A$3:$A$6,0)),"")) -> Golden yellow with light brown at some edges or small spots | H61: =IF(F61="","",IFERROR(INDEX(Bands!$J$3:$J$6,MATCH(F61,Bands!$A$3:$A$6,0)),"")) -> Not pale yellow (matches a low value) and not deep reddish-brown (matches a high value). Avoid black or burnt chips. | I61: =IF(F61="","","Ch3_"&TEXT(COUNT($E$2:E61),"000")&"_"&SUBSTITUTE(F61," ","-")&"_"&TEXT(E61,"0")&".jpg") -> Ch3_058_Medium_519.jpg
B62: 11 | C62: 1.0383 | D62: 94.411 | E62: =D62*10/C62 -> 909.28441 | F62: =IF(NOT(ISNUMBER(E62)),"",IF(E62<Bands!$B$4,"Low",IF(E62<Bands!$B$5,"Medium",IF(E62<Bands!$B$6,"High","Very high")))) -> Medium | G62: =IF(F62="","",IFERROR(INDEX(Bands!$D$3:$D$6,MATCH(F62,Bands!$A$3:$A$6,0)),"")) -> Golden yellow with light brown at some edges or small spots | H62: =IF(F62="","",IFERROR(INDEX(Bands!$J$3:$J$6,MATCH(F62,Bands!$A$3:$A$6,0)),"")) -> Not pale yellow (matches a low value) and not deep reddish-brown (matches a high value). Avoid black or burnt chips. | I62: =IF(F62="","","Ch3_"&TEXT(COUNT($E$2:E62),"000")&"_"&SUBSTITUTE(F62," ","-")&"_"&TEXT(E62,"0")&".jpg") -> Ch3_059_Medium_909.jpg
...

Sheet Chapter 4
A1: 1st trial | B1: Days after treatment | C1: Cultivar/Condition | D1: Sample | E1: Mass (g) | F1: Acrylamide in vial (ppb) | G1: Acrylamide in sample (µg/kg) | H1: Colour parameters | I1: L | J1: a | K1: b | M1: 2nd trial | N1: Cultivar/Condition | O1: Sample | P1: Mass (g) | Q1: Acrylamide in vial (ppb) | R1: Acrylamide in sample (µg/kg) | S1: Colour parameters | T1: L | U1: a | V1: b | W1: Acrylamide band (1st trial) | X1: Acrylamide band (2nd trial) | Y1: Colour category (1st trial, from a*) | Z1: Colour category (2nd trial, from a*) | AA1: Expected chip colour (1st trial) | AB1: Not like this (1st trial) | AC1: Expected chip colour (2nd trial) | AD1: Not like this (2nd trial) | AE1: Image file name (1st trial) | AF1: Image file name (2nd trial)
B2: T=0 | C2: Lady Claire Mint essential oil controls | D2: 1 | E2: 1.0074 | F2: 18.681398 | G2: 185.44171 | N2: Lady Claire Mint essential oil controls | O2: 1 | P2: 1.0081 | Q2: 26.957249 | R2: 267.40649 | T2: 35.56 | U2: 2.6 | V2: 20.18 | W2: =IF(NOT(ISNUMBER(G2)),"",IF(G2<Bands!$B$4,"Low",IF(G2<Bands!$B$5,"Medium",IF(G2<Bands!$B$6,"High","Very high")))) -> Low | X2: =IF(NOT(ISNUMBER(R2)),"",IF(R2<Bands!$B$4,"Low",IF(R2<Bands!$B$5,"Medium",IF(R2<Bands!$B$6,"High","Very high")))) -> Low | Z2: =IF(NOT(ISNUMBER(U2)),"",IF(U2<Bands!$B$18,"Light",IF(U2<Bands!$B$19,"Medium","Dark"))) -> Light | AA2: =IF(W2="","",IFERROR(INDEX(Bands!$D$3:$D$6,MATCH(W2,Bands!$A$3:$A$6,0)),"")) -> Pale yellow to light golden, even colour, no brown spots | AB2: =IF(W2="","",IFERROR(INDEX(Bands!$J$3:$J$6,MATCH(W2,Bands!$A$3:$A$6,0)),"")) -> Not deep golden-brown or reddish-brown (those match higher values). Avoid black or burnt chips. | AC2: =IF(X2="","",IFERROR(INDEX(Bands!$D$3:$D$6,MATCH(X2,Bands!$A$3:$A$6,0)),"")) -> Pale yellow to light golden, even colour, no brown spots | AD2: =IF(X2="","",IFERROR(INDEX(Bands!$J$3:$J$6,MATCH(X2,Bands!$A$3:$A$6,0)),"")) -> Not deep golden-brown or reddish-brown (those match higher values). Avoid black or burnt chips. | AE2: =IF(W2="","","Ch4a_"&TEXT(COUNT($G$2:G2),"000")&"_"&SUBSTITUTE(W2," ","-")&"_"&TEXT(G2,"0")&".jpg") -> Ch4a_001_Low_185.jpg | AF2: =IF(X2="","","Ch4b_"&TEXT(COUNT($R$2:R2),"000")&"_"&SUBSTITUTE(X2," ","-")&"_"&TEXT(R2,"0")&".jpg") -> Ch4b_001_Low_267.jpg
D3: 2 | E3: 1.0029 | F3: 36.943952 | G3: 368.37125 | O3: 2 | P3: 0.9849 | Q3: 16.440315 | R3: 166.9237 | W3: =IF(NOT(ISNUMBER(G3)),"",IF(G3<Bands!$B$4,"Low",IF(G3<Bands!$B$5,"Medium",IF(G3<Bands!$B$6,"High","Very high")))) -> Low | X3: =IF(NOT(ISNUMBER(R3)),"",IF(R3<Bands!$B$4,"Low",IF(R3<Bands!$B$5,"Medium",IF(R3<Bands!$B$6,"High","Very high")))) -> Low | AA3: =IF(W3="","",IFERROR(INDEX(Bands!$D$3:$D$6,MATCH(W3,Bands!$A$3:$A$6,0)),"")) -> Pale yellow to light golden, even colour, no brown spots | AB3: =IF(W3="","",IFERROR(INDEX(Bands!$J$3:$J$6,MATCH(W3,Bands!$A$3:$A$6,0)),"")) -> Not deep golden-brown or reddish-brown (those match higher values). Avoid black or burnt chips. | AC3: =IF(X3="","",IFERROR(INDEX(Bands!$D$3:$D$6,MATCH(X3,Bands!$A$3:$A$6,0)),"")) -> Pale yellow to light golden, even colour, no brown spots | AD3: =IF(X3="","",IFERROR(INDEX(Bands!$J$3:$J$6,MATCH(X3,Bands!$A$3:$A$6,0)),"")) -> Not deep golden-brown or reddish-brown (those match higher values). Avoid black or burnt chips. | AE3: =IF(W3="","","Ch4a_"&TEXT(COUNT($G$2:G3),"000")&"_"&SUBSTITUTE(W3," ","-")&"_"&TEXT(G3,"0")&".jpg") -> Ch4a_002_Low_368.jpg | AF3: =IF(X3="","","Ch4b_"&TEXT(COUNT($R$2:R3),"000")&"_"&SUBSTITUTE(X3," ","-")&"_"&TEXT(R3,"0")&".jpg") -> Ch4b_002_Low_167.jpg
D4: 3 | E4: 1.0051 | F4: 32.973868 | G4: 328.06555 | O4: 3 | P4: 0.9815 | Q4: 26.610384 | R4: 271.11955 | W4: =IF(NOT(ISNUMBER(G4)),"",IF(G4<Bands!$B$4,"Low",IF(G4<Bands!$B$5,"Medium",IF(G4<Bands!$B$6,"High","Very high")))) -> Low | X4: =IF(NOT(ISNUMBER(R4)),"",IF(R4<Bands!$B$4,"Low",IF(R4<Bands!$B$5,"Medium",IF(R4<Bands!$B$6,"High","Very high")))) -> Low | AA4: =IF(W4="","",IFERROR(INDEX(Bands!$D$3:$D$6,MATCH(W4,Bands!$A$3:$A$6,0)),"")) -> Pale yellow to light golden, even colour, no brown spots | AB4: =IF(W4="","",IFERROR(INDEX(Bands!$J$3:$J$6,MATCH(W4,Bands!$A$3:$A$6,0)),"")) -> Not deep golden-brown or reddish-brown (those match higher values). Avoid black or burnt chips. | AC4: =IF(X4="","",IFERROR(INDEX(Bands!$D$3:$D$6,MATCH(X4,Bands!$A$3:$A$6,0)),"")) -> Pale yellow to light golden, even colour, no brown spots | AD4: =IF(X4="","",IFERROR(INDEX(Bands!$J$3:$J$6,MATCH(X4,Bands!$A$3:$A$6,0)),"")) -> Not deep golden-brown or reddish-brown (those match higher values). Avoid black or burnt chips. | AE4: =IF(W4="","","Ch4a_"&TEXT(COUNT($G$2:G4),"000")&"_"&SUBSTITUTE(W4," ","-")&"_"&TEXT(G4,"0")&".jpg") -> Ch4a_003_Low_328.jpg | AF4: =IF(X4="","","Ch4b_"&TEXT(COUNT($R$2:R4),"000")&"_"&SUBSTITUTE(X4," ","-")&"_"&TEXT(R4,"0")&".jpg") -> Ch4b_003_Low_271.jpg
D5: 4 | E5: 1.004 | F5: 27.252087 | G5: 271.43513 | O5: 4 | P5: 1.0191 | Q5: 52.409859 | R5: 514.27592 | T5: 35.11 | U5: 3.71 | V5: 20.48 | W5: =IF(NOT(ISNUMBER(G5)),"",IF(G5<Bands!$B$4,"Low",IF(G5<Bands!$B$5,"Medium",IF(G5<Bands!$B$6,"High","Very high")))) -> Low | X5: =IF(NOT(ISNUMBER(R5)),"",IF(R5<Bands!$B$4,"Low",IF(R5<Bands!$B$5,"Medium",IF(R5<Bands!$B$6,"High","Very high")))) -> Medium | Z5: =IF(NOT(ISNUMBER(U5)),"",IF(U5<Bands!$B$18,"Light",IF(U5<Bands!$B$19,"Medium","Dark"))) -> Medium | AA5: =IF(W5="","",IFERROR(INDEX(Bands!$D$3:$D$6,MATCH(W5,Bands!$A$3:$A$6,0)),"")) -> Pale yellow to light golden, even colour, no brown spots | AB5: =IF(W5="","",IFERROR(INDEX(Bands!$J$3:$J$6,MATCH(W5,Bands!$A$3:$A$6,0)),"")) -> Not deep golden-brown or reddish-brown (those match higher values). Avoid black or burnt chips. | AC5: =IF(X5="","",IFERROR(INDEX(Bands!$D$3:$D$6,MATCH(X5,Bands!$A$3:$A$6,0)),"")) -> Golden yellow with light brown at some edges or small spots | AD5: =IF(X5="","",IFERROR(INDEX(Bands!$J$3:$J$6,MATCH(X5,Bands!$A$3:$A$6,0)),"")) -> Not pale yellow (matches a low value) and not deep reddish-brown (matches a high value). Avoid black or burnt chips. | AE5: =IF(W5="","","Ch4a_"&TEXT(COUNT($G$2:G5),"000")&"_"&SUBSTITUTE(W5," ","-")&"_"&TEXT(G5,"0")&".jpg") -> Ch4a_004_Low_271.jpg | AF5: =IF(X5="","","Ch4b_"&TEXT(COUNT($R$2:R5),"000")&"_"&SUBSTITUTE(X5," ","-")&"_"&TEXT(R5,"0")&".jpg") -> Ch4b_004_Medium_514.jpg
D6: 5 | E6: 1.0084 | F6: 30.932287 | G6: 306.7462 | O6: 5 | P6: 1.0167 | Q6: 19.479318 | R6: 191.59357 | T6: 33.62 | U6: 2.5 | V6: 18.15 | W6: =IF(NOT(ISNUMBER(G6)),"",IF(G6<Bands!$B$4,"Low",IF(G6<Bands!$B$5,"Medium",IF(G6<Bands!$B$6,"High","Very high")))) -> Low | X6: =IF(NOT(ISNUMBER(R6)),"",IF(R6<Bands!$B$4,"Low",IF(R6<Bands!$B$5,"Medium",IF(R6<Bands!$B$6,"High","Very high")))) -> Low | Z6: =IF(NOT(ISNUMBER(U6)),"",IF(U6<Bands!$B$18,"Light",IF(U6<Bands!$B$19,"Medium","Dark"))) -> Light | AA6: =IF(W6="","",IFERROR(INDEX(Bands!$D$3:$D$6,MATCH(W6,Bands!$A$3:$A$6,0)),"")) -> Pale yellow to light golden, even colour, no brown spots | AB6: =IF(W6="","",IFERROR(INDEX(Bands!$J$3:$J$6,MATCH(W6,Bands!$A$3:$A$6,0)),"")) -> Not deep golden-brown or reddish-brown (those match higher values). Avoid black or burnt chips. | AC6: =IF(X6="","",IFERROR(INDEX(Bands!$D$3:$D$6,MATCH(X6,Bands!$A$3:$A$6,0)),"")) -> Pale yellow to light golden, even colour, no brown spots | AD6: =IF(X6="","",IFERROR(INDEX(Bands!$J$3:$J$6,MATCH(X6,Bands!$A$3:$A$6,0)),"")) -> Not deep golden-brown or reddish-brown (those match higher values). Avoid black or burnt chips. | AE6: =IF(W6="","","Ch4a_"&TEXT(COUNT($G$2:G6),"000")&"_"&SUBSTITUTE(W6," ","-")&"_"&TEXT(G6,"0")&".jpg") -> Ch4a_005_Low_307.jpg | AF6: =IF(X6="","","Ch4b_"&TEXT(COUNT($R$2:R6),"000")&"_"&SUBSTITUTE(X6," ","-")&"_"&TEXT(R6,"0")&".jpg") -> Ch4b_005_Low_192.jpg
D7: 6 | E7: 1.0009 | F7: 36.577105 | G7: 365.44216 | O7: 6 | P7: 0.9882 | Q7: 17.295231 | R7: 175.01752 | W7: =IF(NOT(ISNUMBER(G7)),"",IF(G7<Bands!$B$4,"Low",IF(G7<Bands!$B$5,"Medium",IF(G7<Bands!$B$6,"High","Very high")))) -> Low | X7: =IF(NOT(ISNUMBER(R7)),"",IF(R7<Bands!$B$4,"Low",IF(R7<Bands!$B$5,"Medium",IF(R7<Bands!$B$6,"High","Very high")))) -> Low | AA7: =IF(W7="","",IFERROR(INDEX(Bands!$D$3:$D$6,MATCH(W7,Bands!$A$3:$A$6,0)),"")) -> Pale yellow to light golden, even colour, no brown spots | AB7: =IF(W7="","",IFERROR(INDEX(Bands!$J$3:$J$6,MATCH(W7,Bands!$A$3:$A$6,0)),"")) -> Not deep golden-brown or reddish-brown (those match higher values). Avoid black or burnt chips. | AC7: =IF(X7="","",IFERROR(INDEX(Bands!$D$3:$D$6,MATCH(X7,Bands!$A$3:$A$6,0)),"")) -> Pale yellow to light golden, even colour, no brown spots | AD7: =IF(X7="","",IFERROR(INDEX(Bands!$J$3:$J$6,MATCH(X7,Bands!$A$3:$A$6,0)),"")) -> Not deep golden-brown or reddish-brown (those match higher values). Avoid black or burnt chips. | AE7: =IF(W7="","","Ch4a_"&TEXT(COUNT($G$2:G7),"000")&"_"&SUBSTITUTE(W7," ","-")&"_"&TEXT(G7,"0")&".jpg") -> Ch4a_006_Low_365.jpg | AF7: =IF(X7="","","Ch4b_"&TEXT(COUNT($R$2:R7),"000")&"_"&SUBSTITUTE(X7," ","-")&"_"&TEXT(R7,"0")&".jpg") -> Ch4b_006_Low_175.jpg
B9: T=1 | C9: Lady Claire Mint essential oil treated | D9: 1 | E9: 1.0038 | F9: 45.194914 | G9: 450.23823 | N9: Lady Claire Mint essential oil 1 treatment | O9: 1 | P9: 0.9987 | Q9: 25.9003 | R9: 259.34014 | T9: 32.51 | U9: 3.15 | V9: 18.83 | W9: =IF(NOT(ISNUMBER(G9)),"",IF(G9<Bands!$B$4,"Low",IF(G9<Bands!$B$5,"Medium",IF(G9<Bands!$B$6,"High","Very high")))) -> Low | X9: =IF(NOT(ISNUMBER(R9)),"",IF(R9<Bands!$B$4,"Low",IF(R9<Bands!$B$5,"Medium",IF(R9<Bands!$B$6,"High","Very high")))) -> Low | Z9: =IF(NOT(ISNUMBER(U9)),"",IF(U9<Bands!$B$18,"Light",IF(U9<Bands!$B$19,"Medium","Dark"))) -> Medium | AA9: =IF(W9="","",IFERROR(INDEX(Bands!$D$3:$D$6,MATCH(W9,Bands!$A$3:$A$6,0)),"")) -> Pale yellow to light golden, even colour, no brown spots | AB9: =IF(W9="","",IFERROR(INDEX(Bands!$J$3:$J$6,MATCH(W9,Bands!$A$3:$A$6,0)),"")) -> Not deep golden-brown or reddish-brown (those match higher values). Avoid black or burnt chips. | AC9: =IF(X9="","",IFERROR(INDEX(Bands!$D$3:$D$6,MATCH(X9,Bands!$A$3:$A$6,0)),"")) -> Pale yellow to light golden, even colour, no brown spots | AD9: =IF(X9="","",IFERROR(INDEX(Bands!$J$3:$J$6,MATCH(X9,Bands!$A$3:$A$6,0)),"")) -> Not deep golden-brown or reddish-brown (those match higher values). Avoid black or burnt chips. | AE9: =IF(W9="","","Ch4a_"&TEXT(COUNT($G$2:G9),"000")&"_"&SUBSTITUTE(W9," ","-")&"_"&TEXT(G9,"0")&".jpg") -> Ch4a_007_Low_450.jpg | AF9: =IF(X9="","","Ch4b_"&TEXT(COUNT($R$2:R9),"000")&"_"&SUBSTITUTE(X9," ","-")&"_"&TEXT(R9,"0")&".jpg") -> Ch4b_007_Low_259.jpg
D10: 2 | E10: 1.0071 | F10: 33.488204 | G10: 332.52114 | O10: 2 | P10: 1.027 | Q10: 28.614381 | R10: 278.62104 | W10: =IF(NOT(ISNUMBER(G10)),"",IF(G10<Bands!$B$4,"Low",IF(G10<Bands!$B$5,"Medium",IF(G10<Bands!$B$6,"High","Very high")))) -> Low | X10: =IF(NOT(ISNUMBER(R10)),"",IF(R10<Bands!$B$4,"Low",IF(R10<Bands!$B$5,"Medium",IF(R10<Bands!$B$6,"High","Very high")))) -> Low | AA10: =IF(W10="","",IFERROR(INDEX(Bands!$D$3:$D$6,MATCH(W10,Bands!$A$3:$A$6,0)),"")) -> Pale yellow to light golden, even colour, no brown spots | AB10: =IF(W10="","",IFERROR(INDEX(Bands!$J$3:$J$6,MATCH(W10,Bands!$A$3:$A$6,0)),"")) -> Not deep golden-brown or reddish-brown (those match higher values). Avoid black or burnt chips. | AC10: =IF(X10="","",IFERROR(INDEX(Bands!$D$3:$D$6,MATCH(X10,Bands!$A$3:$A$6,0)),"")) -> Pale yellow to light golden, even colour, no brown spots | AD10: =IF(X10="","",IFERROR(INDEX(Bands!$J$3:$J$6,MATCH(X10,Bands!$A$3:$A$6,0)),"")) -> Not deep golden-brown or reddish-brown (those match higher values). Avoid black or burnt chips. | AE10: =IF(W10="","","Ch4a_"&TEXT(COUNT($G$2:G10),"000")&"_"&SUBSTITUTE(W10," ","-")&"_"&TEXT(G10,"0")&".jpg") -> Ch4a_008_Low_333.jpg | AF10: =IF(X10="","","Ch4b_"&TEXT(COUNT($R$2:R10),"000")&"_"&SUBSTITUTE(X10," ","-")&"_"&TEXT(R10,"0")&".jpg") -> Ch4b_008_Low_279.jpg
D11: 3 | E11: 1.0088 | F11: 47.889941 | G11: 474.72185 | O11: 3 | P11: 1.0332 | Q11: 23.015804 | R11: 222.76234 | T11: 35.78 | U11: 2.51 | V11: 19.8 | W11: =IF(NOT(ISNUMBER(G11)),"",IF(G11<Bands!$B$4,"Low",IF(G11<Bands!$B$5,"Medium",IF(G11<Bands!$B$6,"High","Very high")))) -> Low | X11: =IF(NOT(ISNUMBER(R11)),"",IF(R11<Bands!$B$4,"Low",IF(R11<Bands!$B$5,"Medium",IF(R11<Bands!$B$6,"High","Very high")))) -> Low | Z11: =IF(NOT(ISNUMBER(U11)),"",IF(U11<Bands!$B$18,"Light",IF(U11<Bands!$B$19,"Medium","Dark"))) -> Light | AA11: =IF(W11="","",IFERROR(INDEX(Bands!$D$3:$D$6,MATCH(W11,Bands!$A$3:$A$6,0)),"")) -> Pale yellow to light golden, even colour, no brown spots | AB11: =IF(W11="","",IFERROR(INDEX(Bands!$J$3:$J$6,MATCH(W11,Bands!$A$3:$A$6,0)),"")) -> Not deep golden-brown or reddish-brown (those match higher values). Avoid black or burnt chips. | AC11: =IF(X11="","",IFERROR(INDEX(Bands!$D$3:$D$6,MATCH(X11,Bands!$A$3:$A$6,0)),"")) -> Pale yellow to light golden, even colour, no brown spots | AD11: =IF(X11="","",IFERROR(INDEX(Bands!$J$3:$J$6,MATCH(X11,Bands!$A$3:$A$6,0)),"")) -> Not deep golden-brown or reddish-brown (those match higher values). Avoid black or burnt chips. | AE11: =IF(W11="","","Ch4a_"&TEXT(COUNT($G$2:G11),"000")&"_"&SUBSTITUTE(W11," ","-")&"_"&TEXT(G11,"0")&".jpg") -> Ch4a_009_Low_475.jpg | AF11: =IF(X11="","","Ch4b_"&TEXT(COUNT($R$2:R11),"000")&"_"&SUBSTITUTE(X11," ","-")&"_"&TEXT(R11,"0")&".jpg") -> Ch4b_009_Low_223.jpg
D12: 4 | E12: 1.004 | F12: 44.471024 | G12: 442.93849 | I12: 45.86 | J12: 3.05 | K12: 21.16 | O12: 4 | P12: 1.0324 | Q12: 92.611637 | R12: 897.05189 | W12: =IF(NOT(ISNUMBER(G12)),"",IF(G12<Bands!$B$4,"Low",IF(G12<Bands!$B$5,"Medium",IF(G12<Bands!$B$6,"High","Very high")))) -> Low | X12: =IF(NOT(ISNUMBER(R12)),"",IF(R12<Bands!$B$4,"Low",IF(R12<Bands!$B$5,"Medium",IF(R12<Bands!$B$6,"High","Very high")))) -> Medium | Y12: =IF(NOT(ISNUMBER(J12)),"",IF(J12<Bands!$B$18,"Light",IF(J12<Bands!$B$19,"Medium","Dark"))) -> Medium | AA12: =IF(W12="","",IFERROR(INDEX(Bands!$D$3:$D$6,MATCH(W12,Bands!$A$3:$A$6,0)),"")) -> Pale yellow to light golden, even colour, no brown spots | AB12: =IF(W12="","",IFERROR(INDEX(Bands!$J$3:$J$6,MATCH(W12,Bands!$A$3:$A$6,0)),"")) -> Not deep golden-brown or reddish-brown (those match higher values). Avoid black or burnt chips. | AC12: =IF(X12="","",IFERROR(INDEX(Bands!$D$3:$D$6,MATCH(X12,Bands!$A$3:$A$6,0)),"")) -> Golden yellow with light brown at some edges or small spots | AD12: =IF(X12="","",IFERROR(INDEX(Bands!$J$3:$J$6,MATCH(X12,Bands!$A$3:$A$6,0)),"")) -> Not pale yellow (matches a low value) and not deep reddish-brown (matches a high value). Avoid black or burnt chips. | AE12: =IF(W12="","","Ch4a_"&TEXT(COUNT($G$2:G12),"000")&"_"&SUBSTITUTE(W12," ","-")&"_"&TEXT(G12,"0")&".jpg") -> Ch4a_010_Low_443.jpg | AF12: =IF(X12="","","Ch4b_"&TEXT(COUNT($R$2:R12),"000")&"_"&SUBSTITUTE(X12," ","-")&"_"&TEXT(R12,"0")&".jpg") -> Ch4b_010_Medium_897.jpg
D13: 5 | E13: 1.0055 | F13: 41.165841 | G13: 409.40667 | I13: 34.84 | J13: 3.46 | K13: 20.75 | O13: 5 | P13: 1.0241 | Q13: 69.585421 | R13: 679.47877 | T13: 50.25 | U13: 2.73 | V13: 24.44 | W13: =IF(NOT(ISNUMBER(G13)),"",IF(G13<Bands!$B$4,"Low",IF(G13<Bands!$B$5,"Medium",IF(G13<Bands!$B$6,"High","Very high")))) -> Low | X13: =IF(NOT(ISNUMBER(R13)),"",IF(R13<Bands!$B$4,"Low",IF(R13<Bands!$B$5,"Medium",IF(R13<Bands!$B$6,"High","Very high")))) -> Medium | Y13: =IF(NOT(ISNUMBER(J13)),"",IF(J13<Bands!$B$18,"Light",IF(J13<Bands!$B$19,"Medium","Dark"))) -> Medium | Z13: =IF(NOT(ISNUMBER(U13)),"",IF(U13<Bands!$B$18,"Light",IF(U13<Bands!$B$19,"Medium","Dark"))) -> Light | AA13: =IF(W13="","",IFERROR(INDEX(Bands!$D$3:$D$6,MATCH(W13,Bands!$A$3:$A$6,0)),"")) -> Pale yellow to light golden, even colour, no brown spots | AB13: =IF(W13="","",IFERROR(INDEX(Bands!$J$3:$J$6,MATCH(W13,Bands!$A$3:$A$6,0)),"")) -> Not deep golden-brown or reddish-brown (those match higher values). Avoid black or burnt chips. | AC13: =IF(X13="","",IFERROR(INDEX(Bands!$D$3:$D$6,MATCH(X13,Bands!$A$3:$A$6,0)),"")) -> Golden yellow with light brown at some edges or small spots | AD13: =IF(X13="","",IFERROR(INDEX(Bands!$J$3:$J$6,MATCH(X13,Bands!$A$3:$A$6,0)),"")) -> Not pale yellow (matches a low value) and not deep reddish-brown (matches a high value). Avoid black or burnt chips. | AE13: =IF(W13="","","Ch4a_"&TEXT(COUNT($G$2:G13),"000")&"_"&SUBSTITUTE(W13," ","-")&"_"&TEXT(G13,"0")&".jpg") -> Ch4a_011_Low_409.jpg | AF13: =IF(X13="","","Ch4b_"&TEXT(COUNT($R$2:R13),"000")&"_"&SUBSTITUTE(X13," ","-")&"_"&TEXT(R13,"0")&".jpg") -> Ch4b_011_Medium_679.jpg
D14: 6 | E14: 1.0048 | F14: 35.777532 | G14: 356.0662 | I14: 34.63 | J14: 3.15 | K14: 18.99 | O14: 6 | P14: 1.0117 | Q14: 85.6837 | R14: 846.92795 | W14: =IF(NOT(ISNUMBER(G14)),"",IF(G14<Bands!$B$4,"Low",IF(G14<Bands!$B$5,"Medium",IF(G14<Bands!$B$6,"High","Very high")))) -> Low | X14: =IF(NOT(ISNUMBER(R14)),"",IF(R14<Bands!$B$4,"Low",IF(R14<Bands!$B$5,"Medium",IF(R14<Bands!$B$6,"High","Very high")))) -> Medium | Y14: =IF(NOT(ISNUMBER(J14)),"",IF(J14<Bands!$B$18,"Light",IF(J14<Bands!$B$19,"Medium","Dark"))) -> Medium | AA14: =IF(W14="","",IFERROR(INDEX(Bands!$D$3:$D$6,MATCH(W14,Bands!$A$3:$A$6,0)),"")) -> Pale yellow to light golden, even colour, no brown spots | AB14: =IF(W14="","",IFERROR(INDEX(Bands!$J$3:$J$6,MATCH(W14,Bands!$A$3:$A$6,0)),"")) -> Not deep golden-brown or reddish-brown (those match higher values). Avoid black or burnt chips. | AC14: =IF(X14="","",IFERROR(INDEX(Bands!$D$3:$D$6,MATCH(X14,Bands!$A$3:$A$6,0)),"")) -> Golden yellow with light brown at some edges or small spots | AD14: =IF(X14="","",IFERROR(INDEX(Bands!$J$3:$J$6,MATCH(X14,Bands!$A$3:$A$6,0)),"")) -> Not pale yellow (matches a low value) and not deep reddish-brown (matches a high value). Avoid black or burnt chips. | AE14: =IF(W14="","","Ch4a_"&TEXT(COUNT($G$2:G14),"000")&"_"&SUBSTITUTE(W14," ","-")&"_"&TEXT(G14,"0")&".jpg") -> Ch4a_012_Low_356.jpg | AF14: =IF(X14="","","Ch4b_"&TEXT(COUNT($R$2:R14),"000")&"_"&SUBSTITUTE(X14," ","-")&"_"&TEXT(R14,"0")&".jpg") -> Ch4b_012_Medium_847.jpg
C16: Lady Claire Mint essential oil controls | D16: 1 | E16: 1.0038 | F16: 51.696441 | G16: 515.00738 | N16: Lady Claire Mint essential oil 2 treatments | O16: 1 | P16: 0.9764 | Q16: 13.071622 | R16: 133.87568 | W16: =IF(NOT(ISNUMBER(G16)),"",IF(G16<Bands!$B$4,"Low",IF(G16<Bands!$B$5,"Medium",IF(G16<Bands!$B$6,"High","Very high")))) -> Medium | X16: =IF(NOT(ISNUMBER(R16)),"",IF(R16<Bands!$B$4,"Low",IF(R16<Bands!$B$5,"Medium",IF(R16<Bands!$B$6,"High","Very high")))) -> Low | AA16: =IF(W16="","",IFERROR(INDEX(Bands!$D$3:$D$6,MATCH(W16,Bands!$A$3:$A$6,0)),"")) -> Golden yellow with light brown at some edges or small spots | AB16: =IF(W16="","",IFERROR(INDEX(Bands!$J$3:$J$6,MATCH(W16,Bands!$A$3:$A$6,0)),"")) -> Not pale yellow (matches a low value) and not deep reddish-brown (matches a high value). Avoid black or burnt chips. | AC16: =IF(X16="","",IFERROR(INDEX(Bands!$D$3:$D$6,MATCH(X16,Bands!$A$3:$A$6,0)),"")) -> Pale yellow to light golden, even colour, no brown spots | AD16: =IF(X16="","",IFERROR(INDEX(Bands!$J$3:$J$6,MATCH(X16,Bands!$A$3:$A$6,0)),"")) -> Not deep golden-brown or reddish-brown (those match higher values). Avoid black or burnt chips. | AE16: =IF(W16="","","Ch4a_"&TEXT(COUNT($G$2:G16),"000")&"_"&SUBSTITUTE(W16," ","-")&"_"&TEXT(G16,"0")&".jpg") -> Ch4a_013_Medium_515.jpg | AF16: =IF(X16="","","Ch4b_"&TEXT(COUNT($R$2:R16),"000")&"_"&SUBSTITUTE(X16," ","-")&"_"&TEXT(R16,"0")&".jpg") -> Ch4b_013_Low_134.jpg
D17: 2 | E17: 1.0009 | F17: 44.275469 | G17: 442.35657 | I17: 46.18 | J17: 2.82 | K17: 21.22 | O17: 2 | P17: 0.9766 | Q17: 12.918525 | R17: 132.28062 | T17: 39.52 | U17: 2.26 | V17: 21.01 | W17: =IF(NOT(ISNUMBER(G17)),"",IF(G17<Bands!$B$4,"Low",IF(G17<Bands!$B$5,"Medium",IF(G17<Bands!$B$6,"High","Very high")))) -> Low | X17: =IF(NOT(ISNUMBER(R17)),"",IF(R17<Bands!$B$4,"Low",IF(R17<Bands!$B$5,"Medium",IF(R17<Bands!$B$6,"High","Very high")))) -> Low | Y17: =IF(NOT(ISNUMBER(J17)),"",IF(J17<Bands!$B$18,"Light",IF(J17<Bands!$B$19,"Medium","Dark"))) -> Light | Z17: =IF(NOT(ISNUMBER(U17)),"",IF(U17<Bands!$B$18,"Light",IF(U17<Bands!$B$19,"Medium","Dark"))) -> Light | AA17: =IF(W17="","",IFERROR(INDEX(Bands!$D$3:$D$6,MATCH(W17,Bands!$A$3:$A$6,0)),"")) -> Pale yellow to light golden, even colour, no brown spots | AB17: =IF(W17="","",IFERROR(INDEX(Bands!$J$3:$J$6,MATCH(W17,Bands!$A$3:$A$6,0)),"")) -> Not deep golden-brown or reddish-brown (those match higher values). Avoid black or burnt chips. | AC17: =IF(X17="","",IFERROR(INDEX(Bands!$D$3:$D$6,MATCH(X17,Bands!$A$3:$A$6,0)),"")) -> Pale yellow to light golden, even colour, no brown spots | AD17: =IF(X17="","",IFERROR(INDEX(Bands!$J$3:$J$6,MATCH(X17,Bands!$A$3:$A$6,0)),"")) -> Not deep golden-brown or reddish-brown (those match higher values). Avoid black or burnt chips. | AE17: =IF(W17="","","Ch4a_"&TEXT(COUNT($G$2:G17),"000")&"_"&SUBSTITUTE(W17," ","-")&"_"&TEXT(G17,"0")&".jpg") -> Ch4a_014_Low_442.jpg | AF17: =IF(X17="","","Ch4b_"&TEXT(COUNT($R$2:R17),"000")&"_"&SUBSTITUTE(X17," ","-")&"_"&TEXT(R17,"0")&".jpg") -> Ch4b_014_Low_132.jpg
D18: 3 | E18: 1.0012 | F18: 52.059208 | G18: 519.96812 | I18: 35.91 | J18: 3.81 | K18: 21.31 | O18: 3 | P18: 0.9946 | Q18: 22.237642 | R18: 223.58377 | W18: =IF(NOT(ISNUMBER(G18)),"",IF(G18<Bands!$B$4,"Low",IF(G18<Bands!$B$5,"Medium",IF(G18<Bands!$B$6,"High","Very high")))) -> Medium | X18: =IF(NOT(ISNUMBER(R18)),"",IF(R18<Bands!$B$4,"Low",IF(R18<Bands!$B$5,"Medium",IF(R18<Bands!$B$6,"High","Very high")))) -> Low | Y18: =IF(NOT(ISNUMBER(J18)),"",IF(J18<Bands!$B$18,"Light",IF(J18<Bands!$B$19,"Medium","Dark"))) -> Medium | AA18: =IF(W18="","",IFERROR(INDEX(Bands!$D$3:$D$6,MATCH(W18,Bands!$A$3:$A$6,0)),"")) -> Golden yellow with light brown at some edges or small spots | AB18: =IF(W18="","",IFERROR(INDEX(Bands!$J$3:$J$6,MATCH(W18,Bands!$A$3:$A$6,0)),"")) -> Not pale yellow (matches a low value) and not deep reddish-brown (matches a high value). Avoid black or burnt chips. | AC18: =IF(X18="","",IFERROR(INDEX(Bands!$D$3:$D$6,MATCH(X18,Bands!$A$3:$A$6,0)),"")) -> Pale yellow to light golden, even colour, no brown spots | AD18: =IF(X18="","",IFERROR(INDEX(Bands!$J$3:$J$6,MATCH(X18,Bands!$A$3:$A$6,0)),"")) -> Not deep golden-brown or reddish-brown (those match higher values). Avoid black or burnt chips. | AE18: =IF(W18="","","Ch4a_"&TEXT(COUNT($G$2:G18),"000")&"_"&SUBSTITUTE(W18," ","-")&"_"&TEXT(G18,"0")&".jpg") -> Ch4a_015_Medium_520.jpg | AF18: =IF(X18="","","Ch4b_"&TEXT(COUNT($R$2:R18),"000")&"_"&SUBSTITUTE(X18," ","-")&"_"&TEXT(R18,"0")&".jpg") -> Ch4b_015_Low_224.jpg
D19: 4 | E19: 1.004 | F19: 48.568722 | G19: 483.75221 | O19: 4 | P19: 0.9654 | Q19: 23.418424 | R19: 242.57742 | T19: 29.44 | U19: 2.25 | V19: 15.95 | W19: =IF(NOT(ISNUMBER(G19)),"",IF(G19<Bands!$B$4,"Low",IF(G19<Bands!$B$5,"Medium",IF(G19<Bands!$B$6,"High","Very high")))) -> Low | X19: =IF(NOT(ISNUMBER(R19)),"",IF(R19<Bands!$B$4,"Low",IF(R19<Bands!$B$5,"Medium",IF(R19<Bands!$B$6,"High","Very high")))) -> Low | Z19: =IF(NOT(ISNUMBER(U19)),"",IF(U19<Bands!$B$18,"Light",IF(U19<Bands!$B$19,"Medium","Dark"))) -> Light | AA19: =IF(W19="","",IFERROR(INDEX(Bands!$D$3:$D$6,MATCH(W19,Bands!$A$3:$A$6,0)),"")) -> Pale yellow to light golden, even colour, no brown spots | AB19: =IF(W19="","",IFERROR(INDEX(Bands!$J$3:$J$6,MATCH(W19,Bands!$A$3:$A$6,0)),"")) -> Not deep golden-brown or reddish-brown (those match higher values). Avoid black or burnt chips. | AC19: =IF(X19="","",IFERROR(INDEX(Bands!$D$3:$D$6,MATCH(X19,Bands!$A$3:$A$6,0)),"")) -> Pale yellow to light golden, even colour, no brown spots | AD19: =IF(X19="","",IFERROR(INDEX(Bands!$J$3:$J$6,MATCH(X19,Bands!$A$3:$A$6,0)),"")) -> Not deep golden-brown or reddish-brown (those match higher values). Avoid black or burnt chips. | AE19: =IF(W19="","","Ch4a_"&TEXT(COUNT($G$2:G19),"000")&"_"&SUBSTITUTE(W19," ","-")&"_"&TEXT(G19,"0")&".jpg") -> Ch4a_016_Low_484.jpg | AF19: =IF(X19="","","Ch4b_"&TEXT(COUNT($R$2:R19),"000")&"_"&SUBSTITUTE(X19," ","-")&"_"&TEXT(R19,"0")&".jpg") -> Ch4b_016_Low_243.jpg
D20: 5 | E20: 1.0058 | F20: 37.491466 | G20: 372.7527 | I20: 44.91 | J20: 3.1 | K20: 20.99 | O20: 5 | P20: 0.9782 | Q20: 9.7861722 | R20: 100.04265 | T20: 34.8 | U20: 1.83 | V20: 18.81 | W20: =IF(NOT(ISNUMBER(G20)),"",IF(G20<Bands!$B$4,"Low",IF(G20<Bands!$B$5,"Medium",IF(G20<Bands!$B$6,"High","Very high")))) -> Low | X20: =IF(NOT(ISNUMBER(R20)),"",IF(R20<Bands!$B$4,"Low",IF(R20<Bands!$B$5,"Medium",IF(R20<Bands!$B$6,"High","Very high")))) -> Low | Y20: =IF(NOT(ISNUMBER(J20)),"",IF(J20<Bands!$B$18,"Light",IF(J20<Bands!$B$19,"Medium","Dark"))) -> Medium | Z20: =IF(NOT(ISNUMBER(U20)),"",IF(U20<Bands!$B$18,"Light",IF(U20<Bands!$B$19,"Medium","Dark"))) -> Light | AA20: =IF(W20="","",IFERROR(INDEX(Bands!$D$3:$D$6,MATCH(W20,Bands!$A$3:$A$6,0)),"")) -> Pale yellow to light golden, even colour, no brown spots | AB20: =IF(W20="","",IFERROR(INDEX(Bands!$J$3:$J$6,MATCH(W20,Bands!$A$3:$A$6,0)),"")) -> Not deep golden-brown or reddish-brown (those match higher values). Avoid black or burnt chips. | AC20: =IF(X20="","",IFERROR(INDEX(Bands!$D$3:$D$6,MATCH(X20,Bands!$A$3:$A$6,0)),"")) -> Pale yellow to light golden, even colour, no brown spots | AD20: =IF(X20="","",IFERROR(INDEX(Bands!$J$3:$J$6,MATCH(X20,Bands!$A$3:$A$6,0)),"")) -> Not deep golden-brown or reddish-brown (those match higher values). Avoid black or burnt chips. | AE20: =IF(W20="","","Ch4a_"&TEXT(COUNT($G$2:G20),"000")&"_"&SUBSTITUTE(W20," ","-")&"_"&TEXT(G20,"0")&".jpg") -> Ch4a_017_Low_373.jpg | AF20: =IF(X20="","","Ch4b_"&TEXT(COUNT($R$2:R20),"000")&"_"&SUBSTITUTE(X20," ","-")&"_"&TEXT(R20,"0")&".jpg") -> Ch4b_017_Low_100.jpg
D21: 6 | E21: 1.0048 | F21: 30.096953 | G21: 299.53178 | O21: 6 | P21: 1.0336 | Q21: 11.039504 | R21: 106.80635 | W21: =IF(NOT(ISNUMBER(G21)),"",IF(G21<Bands!$B$4,"Low",IF(G21<Bands!$B$5,"Medium",IF(G21<Bands!$B$6,"High","Very high")))) -> Low | X21: =IF(NOT(ISNUMBER(R21)),"",IF(R21<Bands!$B$4,"Low",IF(R21<Bands!$B$5,"Medium",IF(R21<Bands!$B$6,"High","Very high")))) -> Low | AA21: =IF(W21="","",IFERROR(INDEX(Bands!$D$3:$D$6,MATCH(W21,Bands!$A$3:$A$6,0)),"")) -> Pale yellow to light golden, even colour, no brown spots | AB21: =IF(W21="","",IFERROR(INDEX(Bands!$J$3:$J$6,MATCH(W21,Bands!$A$3:$A$6,0)),"")) -> Not deep golden-brown or reddish-brown (those match higher values). Avoid black or burnt chips. | AC21: =IF(X21="","",IFERROR(INDEX(Bands!$D$3:$D$6,MATCH(X21,Bands!$A$3:$A$6,0)),"")) -> Pale yellow to light golden, even colour, no brown spots | AD21: =IF(X21="","",IFERROR(INDEX(Bands!$J$3:$J$6,MATCH(X21,Bands!$A$3:$A$6,0)),"")) -> Not deep golden-brown or reddish-brown (those match higher values). Avoid black or burnt chips. | AE21: =IF(W21="","","Ch4a_"&TEXT(COUNT($G$2:G21),"000")&"_"&SUBSTITUTE(W21," ","-")&"_"&TEXT(G21,"0")&".jpg") -> Ch4a_018_Low_300.jpg | AF21: =IF(X21="","","Ch4b_"&TEXT(COUNT($R$2:R21),"000")&"_"&SUBSTITUTE(X21," ","-")&"_"&TEXT(R21,"0")&".jpg") -> Ch4b_018_Low_107.jpg
B23: T=7 | C23: Lady Claire Mint essential oil treated | D23: 1 | E23: 1.0037 | F23: 13.548497 | G23: 134.98552 | N23: Taurus Mint essential oil controls | O23: 1 | P23: 1.0273 | Q23: 539.10137 | R23: 5247.7501 | T23: 22.02 | U23: 8.03 | V23: 11.37 | W23: =IF(NOT(ISNUMBER(G23)),"",IF(G23<Bands!$B$4,"Low",IF(G23<Bands!$B$5,"Medium",IF(G23<Bands!$B$6,"High","Very high")))) -> Low | X23: =IF(NOT(ISNUMBER(R23)),"",IF(R23<Bands!$B$4,"Low",IF(R23<Bands!$B$5,"Medium",IF(R23<Bands!$B$6,"High","Very high")))) -> Very high | Z23: =IF(NOT(ISNUMBER(U23)),"",IF(U23<Bands!$B$18,"Light",IF(U23<Bands!$B$19,"Medium","Dark"))) -> Dark | AA23: =IF(W23="","",IFERROR(INDEX(Bands!$D$3:$D$6,MATCH(W23,Bands!$A$3:$A$6,0)),"")) -> Pale yellow to light golden, even colour, no brown spots | AB23: =IF(W23="","",IFERROR(INDEX(Bands!$J$3:$J$6,MATCH(W23,Bands!$A$3:$A$6,0)),"")) -> Not deep golden-brown or reddish-brown (those match higher values). Avoid black or burnt chips. | AC23: =IF(X23="","",IFERROR(INDEX(Bands!$D$3:$D$6,MATCH(X23,Bands!$A$3:$A$6,0)),"")) -> Deep golden-brown to medium brown with a reddish tone; edges darkest, centre golden or light brown | AD23: =IF(X23="","",IFERROR(INDEX(Bands!$J$3:$J$6,MATCH(X23,Bands!$A$3:$A$6,0)),"")) -> Not pale yellow, which would match a low value, or black and burnt, since very dark chips can have lower acrylamide. | AE23: =IF(W23="","","Ch4a_"&TEXT(COUNT($G$2:G23),"000")&"_"&SUBSTITUTE(W23," ","-")&"_"&TEXT(G23,"0")&".jpg") -> Ch4a_019_Low_135.jpg | AF23: =IF(X23="","","Ch4b_"&TEXT(COUNT($R$2:R23),"000")&"_"&SUBSTITUTE(X23," ","-")&"_"&TEXT(R23,"0")&".jpg") -> Ch4b_019_Very-high_5248.jpg
D24: 2 | E24: 1.0039 | F24: 13.567889 | G24: 135.15179 | O24: 2 | P24: 1.0136 | Q24: 33.680383 | R24: 332.28476 | T24: 28.95 | U24: 2.11 | V24: 12.95 | W24: =IF(NOT(ISNUMBER(G24)),"",IF(G24<Bands!$B$4,"Low",IF(G24<Bands!$B$5,"Medium",IF(G24<Bands!$B$6,"High","Very high")))) -> Low | X24: =IF(NOT(ISNUMBER(R24)),"",IF(R24<Bands!$B$4,"Low",IF(R24<Bands!$B$5,"Medium",IF(R24<Bands!$B$6,"High","Very high")))) -> Low | Z24: =IF(NOT(ISNUMBER(U24)),"",IF(U24<Bands!$B$18,"Light",IF(U24<Bands!$B$19,"Medium","Dark"))) -> Light | AA24: =IF(W24="","",IFERROR(INDEX(Bands!$D$3:$D$6,MATCH(W24,Bands!$A$3:$A$6,0)),"")) -> Pale yellow to light golden, even colour, no brown spots | AB24: =IF(W24="","",IFERROR(INDEX(Bands!$J$3:$J$6,MATCH(W24,Bands!$A$3:$A$6,0)),"")) -> Not deep golden-brown or reddish-brown (those match higher values). Avoid black or burnt chips. | AC24: =IF(X24="","",IFERROR(INDEX(Bands!$D$3:$D$6,MATCH(X24,Bands!$A$3:$A$6,0)),"")) -> Pale yellow to light golden, even colour, no brown spots | AD24: =IF(X24="","",IFERROR(INDEX(Bands!$J$3:$J$6,MATCH(X24,Bands!$A$3:$A$6,0)),"")) -> Not deep golden-brown or reddish-brown (those match higher values). Avoid black or burnt chips. | AE24: =IF(W24="","","Ch4a_"&TEXT(COUNT($G$2:G24),"000")&"_"&SUBSTITUTE(W24," ","-")&"_"&TEXT(G24,"0")&".jpg") -> Ch4a_020_Low_135.jpg | AF24: =IF(X24="","","Ch4b_"&TEXT(COUNT($R$2:R24),"000")&"_"&SUBSTITUTE(X24," ","-")&"_"&TEXT(R24,"0")&".jpg") -> Ch4b_020_Low_332.jpg
D25: 3 | E25: 1.0018 | F25: 22.545143 | G25: 225.04635 | O25: 3 | P25: 0.9788 | Q25: 167.65425 | R25: 1712.8551 | W25: =IF(NOT(ISNUMBER(G25)),"",IF(G25<Bands!$B$4,"Low",IF(G25<Bands!$B$5,"Medium",IF(G25<Bands!$B$6,"High","Very high")))) -> Low | X25: =IF(NOT(ISNUMBER(R25)),"",IF(R25<Bands!$B$4,"Low",IF(R25<Bands!$B$5,"Medium",IF(R25<Bands!$B$6,"High","Very high")))) -> High | AA25: =IF(W25="","",IFERROR(INDEX(Bands!$D$3:$D$6,MATCH(W25,Bands!$A$3:$A$6,0)),"")) -> Pale yellow to light golden, even colour, no brown spots | AB25: =IF(W25="","",IFERROR(INDEX(Bands!$J$3:$J$6,MATCH(W25,Bands!$A$3:$A$6,0)),"")) -> Not deep golden-brown or reddish-brown (those match higher values). Avoid black or burnt chips. | AC25: =IF(X25="","",IFERROR(INDEX(Bands!$D$3:$D$6,MATCH(X25,Bands!$A$3:$A$6,0)),"")) -> Golden-brown with a reddish tint, brown edges, somewhat uneven | AD25: =IF(X25="","",IFERROR(INDEX(Bands!$J$3:$J$6,MATCH(X25,Bands!$A$3:$A$6,0)),"")) -> Not pale yellow, which would match a low value. Not black or burnt, since very dark chips can have lower acrylamide. | AE25: =IF(W25="","","Ch4a_"&TEXT(COUNT($G$2:G25),"000")&"_"&SUBSTITUTE(W25," ","-")&"_"&TEXT(G25,"0")&".jpg") -> Ch4a_021_Low_225.jpg | AF25: =IF(X25="","","Ch4b_"&TEXT(COUNT($R$2:R25),"000")&"_"&SUBSTITUTE(X25," ","-")&"_"&TEXT(R25,"0")&".jpg") -> Ch4b_021_High_1713.jpg
D26: 4 | E26: 1.0008 | F26: 29.658432 | G26: 296.34725 | O26: 4 | P26: 0.9704 | Q26: 48.189277 | R26: 496.59189 | W26: =IF(NOT(ISNUMBER(G26)),"",IF(G26<Bands!$B$4,"Low",IF(G26<Bands!$B$5,"Medium",IF(G26<Bands!$B$6,"High","Very high")))) -> Low | X26: =IF(NOT(ISNUMBER(R26)),"",IF(R26<Bands!$B$4,"Low",IF(R26<Bands!$B$5,"Medium",IF(R26<Bands!$B$6,"High","Very high")))) -> Low | AA26: =IF(W26="","",IFERROR(INDEX(Bands!$D$3:$D$6,MATCH(W26,Bands!$A$3:$A$6,0)),"")) -> Pale yellow to light golden, even colour, no brown spots | AB26: =IF(W26="","",IFERROR(INDEX(Bands!$J$3:$J$6,MATCH(W26,Bands!$A$3:$A$6,0)),"")) -> Not deep golden-brown or reddish-brown (those match higher values). Avoid black or burnt chips. | AC26: =IF(X26="","",IFERROR(INDEX(Bands!$D$3:$D$6,MATCH(X26,Bands!$A$3:$A$6,0)),"")) -> Pale yellow to light golden, even colour, no brown spots | AD26: =IF(X26="","",IFERROR(INDEX(Bands!$J$3:$J$6,MATCH(X26,Bands!$A$3:$A$6,0)),"")) -> Not deep golden-brown or reddish-brown (those match higher values). Avoid black or burnt chips. | AE26: =IF(W26="","","Ch4a_"&TEXT(COUNT($G$2:G26),"000")&"_"&SUBSTITUTE(W26," ","-")&"_"&TEXT(G26,"0")&".jpg") -> Ch4a_022_Low_296.jpg | AF26: =IF(X26="","","Ch4b_"&TEXT(COUNT($R$2:R26),"000")&"_"&SUBSTITUTE(X26," ","-")&"_"&TEXT(R26,"0")&".jpg") -> Ch4b_022_Low_497.jpg
